Workbook

Sheet Read Me
A1: Company 140 (AHSAN BUSINESS) - naya product list, client PDF "Items Enventory (1).pdf" se.
A3: Kya check karna hai:
A4: 1. Product Name, Department, Sub Department sahi hain?
A5: 2. Unit (Stock/Sale): jis unit me customer ko bechte hain (PCS / Packet / Box / bag). Stock isi unit me rahega.
A6: 3. Units per Carton: 1 Carton ke ANDAR kitne pieces/packets hain (cartons ki ginti nahi). Jaise 1000 = 1 Carton me 1000 PCS.
A7: "Carton Contains" column yahi seedha likhta hai: "1 Carton = 1,000 PCS". Stock entry (Opening / PO / GRN) pe Carton chunein to system khud PCS me badal dega.
A8: 4. Sale Price per Unit: 1 unit ki sale price. Carton Price khud calculate hota hai (formula).
A9: 5. Peeli (yellow) "Check" wali rows: PDF me shak tha - inhe zaroor dekhein.
A11: Blue text = edit kar sakte hain. Black = formula / system.
A12: Example: "Paper Cup 2.5oz" - Unit PCS, 1 Carton = 2,000 PCS, Sale Price 2.50 per PCS -> Carton Price 5,000.
A14: Naam me "&", "/", "," nahi hain (product form inhe allow nahi karta) - jaise "Hot and Cold", "Without Cut".
A15: Purane 292 products deactivate honge (delete nahi), naye codes 2001 se shuru.

Sheet Products
A1: Item Code | B1: Department | C1: Sub Department | D1: Product Name | E1: Unit (Stock/Sale) | F1: Packing UOM | G1: Units per Carton | H1: Sale Price per Unit (Rs) | I1: Carton Price (Rs) | J1: Cost Price per Unit (Rs) | K1: Carton Contains | L1: Note / Check
A2: 2001 | B2: LP Series | C2: LP Series | D2: LP 1 | E2: Packet | H2: 2080 | I2: =IF(G2="","",G2*H2) | J2: 0 | K2: =IF(G2="","",IF(F2="","","1 "&F2&" = "&TEXT(G2,"#,##0")&" "&E2)) | L2: PDF: Packet Amount, carton qty nahi di
A3: 2002 | B3: LP Series | C3: LP Series | D3: LP 26 | E3: Packet | H3: 1630 | I3: =IF(G3="","",G3*H3) | J3: 0 | K3: =IF(G3="","",IF(F3="","","1 "&F3&" = "&TEXT(G3,"#,##0")&" "&E3)) | L3: PDF: Packet Amount, carton qty nahi di
A4: 2003 | B4: LP Series | C4: LP Series | D4: LP 8 | E4: Packet | H4: 2430 | I4: =IF(G4="","",G4*H4) | J4: 0 | K4: =IF(G4="","",IF(F4="","","1 "&F4&" = "&TEXT(G4,"#,##0")&" "&E4)) | L4: PDF: Packet Amount, carton qty nahi di
A5: 2004 | B5: LP Series | C5: LP Series | D5: LP 9 | E5: Packet | H5: 1150 | I5: =IF(G5="","",G5*H5) | J5: 0 | K5: =IF(G5="","",IF(F5="","","1 "&F5&" = "&TEXT(G5,"#,##0")&" "&E5)) | L5: PDF: Packet Amount, carton qty nahi di
A6: 2005 | B6: LP Series | C6: LP Series | D6: LP 11 | E6: Packet | H6: 925 | I6: =IF(G6="","",G6*H6) | J6: 0 | K6: =IF(G6="","",IF(F6="","","1 "&F6&" = "&TEXT(G6,"#,##0")&" "&E6)) | L6: PDF: Packet Amount, carton qty nahi di
A7: 2006 | B7: LP Series | C7: LP Series | D7: LP 11 Cut | E7: Packet | H7: 925 | I7: =IF(G7="","",G7*H7) | J7: 0 | K7: =IF(G7="","",IF(F7="","","1 "&F7&" = "&TEXT(G7,"#,##0")&" "&E7)) | L7: PDF: Packet Amount, carton qty nahi di
A8: 2007 | B8: LP Series | C8: LP Series | D8: LP 14 | E8: Packet | H8: 850 | I8: =IF(G8="","",G8*H8) | J8: 0 | K8: =IF(G8="","",IF(F8="","","1 "&F8&" = "&TEXT(G8,"#,##0")&" "&E8)) | L8: PDF: Packet Amount, carton qty nahi di
A9: 2008 | B9: LP Series | C9: LP Series | D9: LP 14 Cut | E9: Packet | H9: 850 | I9: =IF(G9="","",G9*H9) | J9: 0 | K9: =IF(G9="","",IF(F9="","","1 "&F9&" = "&TEXT(G9,"#,##0")&" "&E9)) | L9: PDF: Packet Amount, carton qty nahi di
A10: 2009 | B10: LP Series | C10: LP Series | D10: LP 15 | E10: Packet | H10: 1220 | I10: =IF(G10="","",G10*H10) | J10: 0 | K10: =IF(G10="","",IF(F10="","","1 "&F10&" = "&TEXT(G10,"#,##0")&" "&E10)) | L10: PDF: Packet Amount, carton qty nahi di
A11: 2010 | B11: LP Series | C11: LP Series | D11: LP 19 | E11: Packet | H11: 1030 | I11: =IF(G11="","",G11*H11) | J11: 0 | K11: =IF(G11="","",IF(F11="","","1 "&F11&" = "&TEXT(G11,"#,##0")&" "&E11)) | L11: PDF: Packet Amount, carton qty nahi di
A12: 2011 | B12: LP Series | C12: LP Series | D12: LP 24 | E12: Packet | H12: 1230 | I12: =IF(G12="","",G12*H12) | J12: 0 | K12: =IF(G12="","",IF(F12="","","1 "&F12&" = "&TEXT(G12,"#,##0")&" "&E12)) | L12: PDF: Packet Amount, carton qty nahi di
A13: 2012 | B13: LP Series | C13: LP Series | D13: LP 38 | E13: Packet | H13: 450 | I13: =IF(G13="","",G13*H13) | J13: 0 | K13: =IF(G13="","",IF(F13="","","1 "&F13&" = "&TEXT(G13,"#,##0")&" "&E13)) | L13: PDF: Packet Amount, carton qty nahi di
A14: 2013 | B14: Thermopile Cups | C14: Thermopile Cups | D14: Thermopile Cup Mega Pack | E14: PCS | F14: Carton | G14: 1000 | H14: 4 | I14: =IF(G14="","",G14*H14) | J14: 0 | K14: =IF(G14="","",IF(F14="","","1 "&F14&" = "&TEXT(G14,"#,##0")&" "&E14))
A15: 2014 | B15: Thermopile Cups | C15: Thermopile Cups | D15: Thermopile Cup Sky | E15: PCS | F15: Carton | G15: 1000 | H15: 4 | I15: =IF(G15="","",G15*H15) | J15: 0 | K15: =IF(G15="","",IF(F15="","","1 "&F15&" = "&TEXT(G15,"#,##0")&" "&E15))
A16: 2015 | B16: Thermopile Cups | C16: Thermopile Cups | D16: Thermopile Cup Hot and Cold | E16: PCS | F16: Carton | G16: 1000 | H16: 4 | I16: =IF(G16="","",G16*H16) | J16: 0 | K16: =IF(G16="","",IF(F16="","","1 "&F16&" = "&TEXT(G16,"#,##0")&" "&E16))
A17: 2016 | B17: Paper Cups | C17: Paper Cups | D17: Paper Cup 2.5oz | E17: PCS | F17: Carton | G17: 2000 | H17: 2.5 | I17: =IF(G17="","",G17*H17) | J17: 0 | K17: =IF(G17="","",IF(F17="","","1 "&F17&" = "&TEXT(G17,"#,##0")&" "&E17))
A18: 2017 | B18: Paper Cups | C18: Paper Cups | D18: Paper Cup Imported 4oz | E18: PCS | F18: Carton | G18: 2000 | H18: 2 | I18: =IF(G18="","",G18*H18) | J18: 0 | K18: =IF(G18="","",IF(F18="","","1 "&F18&" = "&TEXT(G18,"#,##0")&" "&E18))
A19: 2018 | B19: Paper Cups | C19: Paper Cups | D19: Paper Cup Local Pearl Pack 7oz | E19: PCS | F19: Carton | G19: 2000 | H19: 2.5 | I19: =IF(G19="","",G19*H19) | J19: 0 | K19: =IF(G19="","",IF(F19="","","1 "&F19&" = "&TEXT(G19,"#,##0")&" "&E19))
A20: 2019 | B20: Paper Cups | C20: Paper Cups | D20: Paper Cup Local Vork 7oz | E20: PCS | F20: Carton | G20: 2000 | H20: 2.5 | I20: =IF(G20="","",G20*H20) | J20: 0 | K20: =IF(G20="","",IF(F20="","","1 "&F20&" = "&TEXT(G20,"#,##0")&" "&E20))
A21: 2020 | B21: Paper Cups | C21: Paper Cups | D21: Paper Cup Local Vork 5oz | E21: PCS | F21: Carton | G21: 2000 | H21: 2.3 | I21: =IF(G21="","",G21*H21) | J21: 0 | K21: =IF(G21="","",IF(F21="","","1 "&F21&" = "&TEXT(G21,"#,##0")&" "&E21))
A22: 2021 | B22: Paper Cups | C22: Paper Cups | D22: Paper Cup Local Pearl Pack 5oz | E22: PCS | F22: Carton | G22: 2000 | H22: 2.3 | I22: =IF(G22="","",G22*H22) | J22: 0 | K22: =IF(G22="","",IF(F22="","","1 "&F22&" = "&TEXT(G22,"#,##0")&" "&E22))
A23: 2022 | B23: Paper Cups | C23: Paper Cups | D23: Paper Cup Local EZY 5oz | E23: PCS | F23: Carton | G23: 2000 | H23: 2.3 | I23: =IF(G23="","",G23*H23) | J23: 0 | K23: =IF(G23="","",IF(F23="","","1 "&F23&" = "&TEXT(G23,"#,##0")&" "&E23))
A24: 2023 | B24: Paper Cups | C24: Paper Cups | D24: Paper Cup Imported 5oz | E24: PCS | F24: Carton | G24: 2000 | H24: 2.3 | I24: =IF(G24="","",G24*H24) | J24: 0 | K24: =IF(G24="","",IF(F24="","","1 "&F24&" = "&TEXT(G24,"#,##0")&" "&E24))
A25: 2024 | B25: Paper Cups | C25: Paper Cups | D25: Handle Paper Cup Imported 7oz | E25: PCS | F25: Carton | G25: 2000 | H25: 3.5 | I25: =IF(G25="","",G25*H25) | J25: 0 | K25: =IF(G25="","",IF(F25="","","1 "&F25&" = "&TEXT(G25,"#,##0")&" "&E25))
... A50: 2049 | B50: Plastic Cups | C50: 200ml Bowl | D50: World Pack 200ml | E50: PCS | F50: Carton | G50: 2000 | H50: 3 | I50: =IF(G50="","",G50*H50) | J50: 0 | K50: =IF(G50="","",IF(F50="","","1 "&F50&" = "&TEXT(G50,"#,##0")&" "&E50))
A51: 2050 | B51: Plastic Cups | C51: 200ml Bowl | D51: Milky Lid Without Cut 200ml | E51: PCS | F51: Carton | G51: 2000 | H51: 1.5 | I51: =IF(G51="","",G51*H51) | J51: 0 | K51: =IF(G51="","",IF(F51="","","1 "&F51&" = "&TEXT(G51,"#,##0")&" "&E51)) | L51: PDF: "W/O cut"
A52: 2051 | B52: Plastic Cups | C52: 150ml Bowl | D52: 150ml KR | E52: PCS | F52: Carton | G52: 1000 | H52: 7.5 | I52: =IF(G52="","",G52*H52) | J52: 0 | K52: =IF(G52="","",IF(F52="","","1 "&F52&" = "&TEXT(G52,"#,##0")&" "&E52))
A53: 2052 | B53: Plastic Cups | C53: 150ml Bowl | D53: 150ml KR Lid | E53: PCS | F53: Carton | G53: 1000 | H53: 3 | I53: =IF(G53="","",G53*H53) | J53: 0 | K53: =IF(G53="","",IF(F53="","","1 "&F53&" = "&TEXT(G53,"#,##0")&" "&E53))
A54: 2053 | B54: Plastic Cups | C54: 150ml Bowl | D54: 150ml World Pack | E54: PCS | F54: Carton | G54: 1000 | H54: 7.5 | I54: =IF(G54="","",G54*H54) | J54: 0 | K54: =IF(G54="","",IF(F54="","","1 "&F54&" = "&TEXT(G54,"#,##0")&" "&E54))
A55: 2054 | B55: Plastic Cups | C55: 150ml Bowl | D55: 150ml World Pack Lid | E55: PCS | F55: Carton | G55: 1000 | H55: 3 | I55: =IF(G55="","",G55*H55) | J55: 0 | K55: =IF(G55="","",IF(F55="","","1 "&F55&" = "&TEXT(G55,"#,##0")&" "&E55))
A56: 2055 | B56: Dip Sauce | C56: KR | D56: 1.5oz KR Cristal | E56: PCS | F56: Carton | G56: 4000 | H56: 2 | I56: =IF(G56="","",G56*H56) | J56: 0 | K56: =IF(G56="","",IF(F56="","","1 "&F56&" = "&TEXT(G56,"#,##0")&" "&E56))
A57: 2056 | B57: Dip Sauce | C57: KR | D57: 1.5oz KR Black | E57: PCS | F57: Carton | G57: 4000 | H57: 2 | I57: =IF(G57="","",G57*H57) | J57: 0 | K57: =IF(G57="","",IF(F57="","","1 "&F57&" = "&TEXT(G57,"#,##0")&" "&E57))
A58: 2057 | B58: Dip Sauce | C58: KR | D58: 02oz KR Cristal | E58: PCS | F58: Carton | G58: 4000 | H58: 3 | I58: =IF(G58="","",G58*H58) | J58: 0 | K58: =IF(G58="","",IF(F58="","","1 "&F58&" = "&TEXT(G58,"#,##0")&" "&E58))
A59: 2058 | B59: Dip Sauce | C59: KR | D59: 02oz KR Black | E59: PCS | F59: Carton | G59: 4000 | H59: 3 | I59: =IF(G59="","",G59*H59) | J59: 0 | K59: =IF(G59="","",IF(F59="","","1 "&F59&" = "&TEXT(G59,"#,##0")&" "&E59))
A60: 2059 | B60: Dip Sauce | C60: KR | D60: 1.5oz KR Lid | E60: PCS | F60: Carton | G60: 4000 | H60: 1 | I60: =IF(G60="","",G60*H60) | J60: 0 | K60: =IF(G60="","",IF(F60="","","1 "&F60&" = "&TEXT(G60,"#,##0")&" "&E60)) | L60: PDF: "1.5 0z Lid"
A61: 2060 | B61: Dip Sauce | C61: KR | D61: 1.5oz World Pack | E61: PCS | F61: Carton | G61: 4000 | H61: 2.3 | I61: =IF(G61="","",G61*H61) | J61: 0 | K61: =IF(G61="","",IF(F61="","","1 "&F61&" = "&TEXT(G61,"#,##0")&" "&E61))
A62: 2061 | B62: Dip Sauce | C62: KR | D62: 1.5oz World Pack Lid | E62: PCS | F62: Carton | G62: 4000 | H62: 1 | I62: =IF(G62="","",G62*H62) | J62: 0 | K62: =IF(G62="","",IF(F62="","","1 "&F62&" = "&TEXT(G62,"#,##0")&" "&E62))
A63: 2062 | B63: Dip Sauce | C63: 01oz Attach | D63: 01oz Huzaifa Sauce Cup | E63: PCS | F63: Carton | G63: 3000 | H63: 2.3 | I63: =IF(G63="","",G63*H63) | J63: 0 | K63: =IF(G63="","",IF(F63="","","1 "&F63&" = "&TEXT(G63,"#,##0")&" "&E63))
A64: 2063 | B64: Dip Sauce | C64: 01oz Attach | D64: 01oz CP Sauce Cup | E64: PCS | F64: Carton | G64: 3000 | H64: 2.3 | I64: =IF(G64="","",G64*H64) | J64: 0 | K64: =IF(G64="","",IF(F64="","","1 "&F64&" = "&TEXT(G64,"#,##0")&" "&E64))
...

Sheet Summary
A1: Department | B1: Sub Departments | C1: Products | D1: Items with Check
A2: LP Series | B2: 1 | C2: =COUNTIF(Products!$B$2:$B$349,A2) | D2: =COUNTIFS(Products!$B$2:$B$349,A2,Products!$L$2:$L$349,"*Check*")
A3: Thermopile Cups | B3: 1 | C3: =COUNTIF(Products!$B$2:$B$349,A3) | D3: =COUNTIFS(Products!$B$2:$B$349,A3,Products!$L$2:$L$349,"*Check*")
A4: Paper Cups | B4: 5 | C4: =COUNTIF(Products!$B$2:$B$349,A4) | D4: =COUNTIFS(Products!$B$2:$B$349,A4,Products!$L$2:$L$349,"*Check*")
A5: Plastic Cups | B5: 4 | C5: =COUNTIF(Products!$B$2:$B$349,A5) | D5: =COUNTIFS(Products!$B$2:$B$349,A5,Products!$L$2:$L$349,"*Check*")
A6: Dip Sauce | B6: 4 | C6: =COUNTIF(Products!$B$2:$B$349,A6) | D6: =COUNTIFS(Products!$B$2:$B$349,A6,Products!$L$2:$L$349,"*Check*")
A7: Dom Glass | B7: 7 | C7: =COUNTIF(Products!$B$2:$B$349,A7) | D7: =COUNTIFS(Products!$B$2:$B$349,A7,Products!$L$2:$L$349,"*Check*")
A8: Faloda Glass | B8: 1 | C8: =COUNTIF(Products!$B$2:$B$349,A8) | D8: =COUNTIFS(Products!$B$2:$B$349,A8,Products!$L$2:$L$349,"*Check*")
A9: Plastic Glass | B9: 5 | C9: =COUNTIF(Products!$B$2:$B$349,A9) | D9: =COUNTIFS(Products!$B$2:$B$349,A9,Products!$L$2:$L$349,"*Check*")
A10: Aluminum Foil | B10: 3 | C10: =COUNTIF(Products!$B$2:$B$349,A10) | D10: =COUNTIFS(Products!$B$2:$B$349,A10,Products!$L$2:$L$349,"*Check*")
A11: Plates | B11: 3 | C11: =COUNTIF(Products!$B$2:$B$349,A11) | D11: =COUNTIFS(Products!$B$2:$B$349,A11,Products!$L$2:$L$349,"*Check*")
A12: H Series | B12: 1 | C12: =COUNTIF(Products!$B$2:$B$349,A12) | D12: =COUNTIFS(Products!$B$2:$B$349,A12,Products!$L$2:$L$349,"*Check*")
A13: W Series | B13: 2 | C13: =COUNTIF(Products!$B$2:$B$349,A13) | D13: =COUNTIFS(Products!$B$2:$B$349,A13,Products!$L$2:$L$349,"*Check*")
... A20: Egg Tray | B20: 1 | C20: =COUNTIF(Products!$B$2:$B$349,A20) | D20: =COUNTIFS(Products!$B$2:$B$349,A20,Products!$L$2:$L$349,"*Check*")
A21: Total | B21: =SUM(B2:B20) | C21: =SUM(C2:C20) | D21: =SUM(D2:D20)
